Workbook

Sheet 데이터 유형
A1: 유형식별자 | B1: 데이터 유형
A2: DT-01 | B2: 임상 데이터
A3: DT-02 | B3: 역학 데이터
A4: DT-03 | B4: 환경 데이터
A5: DT-04 | B5: 사회·행태 데이터
A6: DT-05 | B6: 공중보건 정책 데이터
A7: DT-06 | B7: 의료자원 데이터
A8: DT-07 | B8: 진료지원 인프라 데이터
A9: DT-08 | B9: 의약품 및 처방 데이터

Sheet 데이터 요구사항
Q1: 아이브랩 의견
P2: *미확인 부분의 정의 및 그에 대한 대안책 제시가 전체적으로 필요함 *데이터소스 탭에 있는 정보 이 탭에 통합하여 보는 것이 필요(제공방식,주기 등) | Q2: * 데이터 소스 식별 및 제공소스 확인은 본과제전체적으로 함께 공유/협력할 사항으로 봄 - 기능개발을 위해서는 synthetic data 생성하여 활용은 가능 - 그외에는 실제 제공되고 있거나, 존재가 확인될 필요가 있음 * 데이터셋ID를 통해 데이터소스시트값 참조하도록 통합처리함
A3: 식별자 | B3: 필요 데이터 | C3: 카테고리 | D3: 데이터 소스ID | E3: 제공기관명 | F3: 서비스명 | G3: 서비스URL | H3: 제공방식 | I3: 제공주기 | J3: 제공기관 | K3: 서비스명 | L3: 검토의견 | M3: 1차검토자 | N3: 2차 | O3: 추가의견 | P3: 전북대 의견
A4: R01 | B4: 공개의료데이터셋 (예: VQA-Med ) | C4: 임상 데이터 | E4: =VLOOKUP($D4,데이터소스!$A$3:$F$20,2, FALSE) -> #N/A | F4: =VLOOKUP($D4,데이터소스!$A$3:$F$20,3, FALSE) -> #N/A | G4: =VLOOKUP($D4,데이터소스!$A$3:$F$20,4, FALSE) -> #N/A | H4: =VLOOKUP($D4,데이터소스!$A$3:$F$20,5, FALSE) -> #N/A | I4: =VLOOKUP($D4,데이터소스!$A$3:$F$20,6, FALSE) -> #N/A | L4: - 감염병에 특화된 데이터 미확인 - VQA-MED 2018~2020, VQA-RAD, etc. | M4: 최영준 | N4: 박성식 | O4: - 1차 검토의견과 동일 | P4: MIMIC-IV 의료데이터셋(임상) 소스사이트의 전북대 계정 생성 완료. VQA-Med는 더 찾아봐야 하나, MIMIC-IV 파생 영상의학이미지 데이터셋 확인됨 | Q4: 안내요망
A5: R02 | B5: 감염자 수(주별·월별 발생률) | C5: 역학 데이터 | D5: DS-0101 | E5: =VLOOKUP($D5,데이터소스!$A$3:$F$20,2, FALSE) -> 질병관리청(KDCA) | F5: =VLOOKUP($D5,데이터소스!$A$3:$F$20,3, FALSE) -> 감염병 포털-전수감시 감염병(기간별 통계) | G5: =VLOOKUP($D5,데이터소스!$A$3:$F$20,4, FALSE) -> https://dportal.kdca.go.kr/pot/is/summaryEDW.do | H5: =VLOOKUP($D5,데이터소스!$A$3:$F$20,5, FALSE) -> 파일(xml, csv) | I5: =VLOOKUP($D5,데이터소스!$A$3:$F$20,6, FALSE) -> 년, 월, 주 | J5: 질병관리청(KDCA) | K5: 지역별 감염병 발생현황(질병별 연도별 월별 기간별_ 통계) | L5: - 주요통계(기간별), 주요통계(지역별), 주요통계(성별/연령별), - 감염병별, 지역별, 성별/연령별 감염병 통계 확인 | M5: 최영준 | N5: 박성식 | O5: - 1차 검토의견과 동일 | P5: 제시한 링크상에는 1~3급 감염병만 포함하여(신종, 동물) 과제가 타겟팅하는 일반적인 (계절성) 인플루엔자 데이터 포함하고 있지 않은 것 같으므로 확인이 필요하고, 해당 데이터 수집가능한 다른 루트 조사 필요함. KDCA에서는 인플루엔자 통계데이터 확인되지 않아서 WHO FluNet 참고하는 것 제안 | Q5: - 표본감시감염병 부분에 '인플루엔자' 통계치가 해당하는지 검토 요망 - WHO FlueNet의 수집/적재는 가능하나, 활용대상인지 여부 확정 요망 | R5: https://app.powerbi.com/view?r=eyJrIjoiNjViM2Y4NjktMjJmMC00Y2NjLWFmOWQtODQ0NjZkNWM1YzNmIiwidCI6ImY2MTBjMGI3LWJkMjQtNGIzOS04MTBiLTNkYzI4MGFmYjU5MCIsImMiOjh9
A6: R03 | B6: 감염 재생산지수 | C6: 공중보건 정책 데이터 | E6: =VLOOKUP($D6,데이터소스!$A$3:$F$20,2, FALSE) -> #N/A | F6: =VLOOKUP($D6,데이터소스!$A$3:$F$20,3, FALSE) -> #N/A | G6: =VLOOKUP($D6,데이터소스!$A$3:$F$20,4, FALSE) -> #N/A | H6: =VLOOKUP($D6,데이터소스!$A$3:$F$20,5, FALSE) -> #N/A | I6: =VLOOKUP($D6,데이터소스!$A$3:$F$20,6, FALSE) -> #N/A | L6: - 구조화된 개방 데이터 미확인 - 코로나19 발생주차에 따른 감염재생산지수 제공(게시판 게시물) 참고) https://www.kdca.go.kr/filepath/boardDownload.es?bid=0034&list_no=712025&seq=1 | M6: 최영준 | N6: 박성식 | O6: - 참고) 주요 질병별 기초감염재생산수 https://ko.wikipedia.org/wiki/%EA%B8%B0%EC%B4%88%EA%B0%90%EC%97%BC%EC%9E%AC%EC%83%9D%EC%82%B0%EC%88%98 | P6: 필수데이터이므로 가져올 수 있는 방안 검토 요청 (PDF의 경우 추출) | Q6: - 갱신주기가 빈번하지 않과 데이터 양이 많이 않은 데이터를 자동처리하는것은 비효율적이므로, 참고가 필요한 데이터의 경우 데이터 입력페이지 구성을 통해 제공 고려 필요
A7: R04 | B7: 격리시설 및 음압치료가능병원 | C7: 진료지원 인프라 데이터 | D7: DS-0502 | E7: =VLOOKUP($D7,데이터소스!$A$3:$F$20,2, FALSE) -> 공공데이터포털(data.go.kr) | F7: =VLOOKUP($D7,데이터소스!$A$3:$F$20,3, FALSE) -> 건강보험심사평가원_의료기관별 감염병 및 중증환자 치료시설 현황 | G7: =VLOOKUP($D7,데이터소스!$A$3:$F$20,4, FALSE) -> https://www.data.go.kr/data/15085951/fileData.do | H7: =VLOOKUP($D7,데이터소스!$A$3:$F$20,5, FALSE) -> 파일 | I7: =VLOOKUP($D7,데이터소스!$A$3:$F$20,6, FALSE) -> 비정기 | J7: 공공데이터포털(data.go.kr) | K7: 건강보험심사평가원_의료기관별 감염병 및 중증환자 치료시설 현황 | L7: - 2024. 06월 말 자료 - 전국 의료기관의 중환자실 및 격리병실 병상 정보 제공 | M7: 최영준 | N7: 박성식 | O7: - 1차 검토의견과 동일
A8: R05 | B8: 교통량 | C8: 진료지원 인프라 데이터 | D8: DS-1001 | E8: =VLOOKUP($D8,데이터소스!$A$3:$F$20,2, FALSE) -> 한국도로공사 | F8: =VLOOKUP($D8,데이터소스!$A$3:$F$20,3, FALSE) -> 실시간 전국 교통량 | G8: =VLOOKUP($D8,데이터소스!$A$3:$F$20,4, FALSE) -> https://data.ex.co.kr/openapi/basicinfo/openApiInfoM?apiId=0102&serviceType=&keyWord=&searchDayFrom=undefined&searchDayTo=undefined&CATEGORY=TR&GROUP_TR=&sId=174 | H8: =VLOOKUP($D8,데이터소스!$A$3:$F$20,5, FALSE) -> OpenAPI | I8: =VLOOKUP($D8,데이터소스!$A$3:$F$20,6, FALSE) -> 1시간,15분,5분 | J8: 한국도로공사 | K8: 실시간 전국 교통량 | L8: - 1시간, 15분, 5분 단위 전국 교통량 제공 | M8: 최영준 | N8: 박성식 | O8: - 1차 검토의견과 동일, 차량 대수로 제공 - 고속도로 노선별 방향별 일별 15분 구간교통량 정보도 존재 - 국도, 일반로의 경우 데이터 존재하지 않음
A9: R06 | B9: 교통상황 및 병원까지 접근성 | E9: =VLOOKUP($D9,데이터소스!$A$3:$F$20,2, FALSE) -> #N/A | F9: =VLOOKUP($D9,데이터소스!$A$3:$F$20,3, FALSE) -> #N/A | G9: =VLOOKUP($D9,데이터소스!$A$3:$F$20,4, FALSE) -> #N/A | H9: =VLOOKUP($D9,데이터소스!$A$3:$F$20,5, FALSE) -> #N/A | I9: =VLOOKUP($D9,데이터소스!$A$3:$F$20,6, FALSE) -> #N/A | L9: - 미확인 | M9: 최영준 | N9: 박성식 | O9: - 1차 검토의견과 동일
A10: R07 | B10: 구급차량 및 이송 인력현황 | C10: 진료지원 인프라 데이터 | D10: DS-1101 | E10: =VLOOKUP($D10,데이터소스!$A$3:$F$20,2, FALSE) -> 경기데이터드림 | F10: =VLOOKUP($D10,데이터소스!$A$3:$F$20,3, FALSE) -> 경기도 구급차 및 구급대원 현황 | G10: =VLOOKUP($D10,데이터소스!$A$3:$F$20,4, FALSE) -> https://data.gg.go.kr/portal/data/service/selectServicePage.do?page=1&rows=10&sortColumn=&sortDirection=&infId=JE55Y365432IZR9CT9R926586107&infSeq=2 | H10: =VLOOKUP($D10,데이터소스!$A$3:$F$20,5, FALSE) -> OpenAPI | I10: =VLOOKUP($D10,데이터소스!$A$3:$F$20,6, FALSE) -> 년 | J10: 경기데이터드림 | K10: 경기도 구급차 및 구급대원 현황 | L10: - 경기도 한정 - 구급차수, 구급대원 수 확인 가능 | M10: 최영준 | N10: 박성식 | O10: - 연간, 시도별 구급차수 및 응급구조사 수 통계 존재 참고) https://kosis.kr/statHtml/statHtml.do?orgId=411&tblId=DT_41104_421&conn_path=I2
A11: R08 | B11: 도시화율 | C11: 진료지원 인프라 데이터 | E11: =VLOOKUP($D11,데이터소스!$A$3:$F$20,2, FALSE) -> #N/A | F11: =VLOOKUP($D11,데이터소스!$A$3:$F$20,3, FALSE) -> #N/A | G11: =VLOOKUP($D11,데이터소스!$A$3:$F$20,4, FALSE) -> #N/A | H11: =VLOOKUP($D11,데이터소스!$A$3:$F$20,5, FALSE) -> #N/A | I11: =VLOOKUP($D11,데이터소스!$A$3:$F$20,6, FALSE) -> #N/A | L11: - 구조화된 개방 데이터 미확인 - 통계청 자료 :통계적 지역분류체계로 본 도시화 현황 -참고) https://kostat.go.kr/board.es?mid=a10301010000&bid=246&list_no=429573&act=view&mainXml=Y | M11: 최영준 | N11: 박성식 | O11: - 시군구별 연도별 도시화율(도시지역 인구비율) 데이터 존재 참고) https://www.index.go.kr/unity/potal/main/EachDtlPageDetail.do?idx_cd=1200
A12: R09 | B12: 방역 정책 및 대응조치 | C12: 공중보건 정책 데이터 | E12: =VLOOKUP($D12,데이터소스!$A$3:$F$20,2, FALSE) -> #N/A | F12: =VLOOKUP($D12,데이터소스!$A$3:$F$20,3, FALSE) -> #N/A | G12: =VLOOKUP($D12,데이터소스!$A$3:$F$20,4, FALSE) -> #N/A | H12: =VLOOKUP($D12,데이터소스!$A$3:$F$20,5, FALSE) -> #N/A | I12: =VLOOKUP($D12,데이터소스!$A$3:$F$20,6, FALSE) -> #N/A | L12: '- 구조화된 개방 데이터 미확인 - 참고) 질병관리청 코로나 19 대응 백서: https://www.kdca.go.kr/board/board.es?mid=a20504000000&bid=0014&list_no=727575&act=view | M12: 최영준 | N12: 박성식 | O12: - 1차 검토의견과 동일 | P12: 초록색으로 수정 필요 필수데이터이므로 가져올 수 있는 방안 검토 요청 Google Trend 등 소셜미디어 API 활용방안 검토 요청 | Q12: - 참조성 데이터로 자동처리보다는 정책/대응조치 데이터를 구조화하고 해당 데이터를 입력/관리 할수 있는 페이지 구성이 적합하다고 판단됨
A13: R10 | B13: 방역정책(마스크,모임등) | C13: 공중보건 정책 데이터 | E13: =VLOOKUP($D13,데이터소스!$A$3:$F$20,2, FALSE) -> #N/A | F13: =VLOOKUP($D13,데이터소스!$A$3:$F$20,3, FALSE) -> #N/A | G13: =VLOOKUP($D13,데이터소스!$A$3:$F$20,4, FALSE) -> #N/A | H13: =VLOOKUP($D13,데이터소스!$A$3:$F$20,5, FALSE) -> #N/A | I13: =VLOOKUP($D13,데이터소스!$A$3:$F$20,6, FALSE) -> #N/A | L13: '- 구조화된 개방 데이터 미확인 - 참고) 질병관리청 코로나 19 대응 백서: https://www.kdca.go.kr/board/board.es?mid=a20504000000&bid=0014&list_no=727575&act=view | M13: 최영준 | N13: 박성식 | O13: - 1차 검토의견과 동일 | P13: 초록색으로 수정 필요 필수데이터이므로 가져올 수 있는 방안 검토 요청 Google Trend 등 소셜미디어 API 활용방안 검토 요청 | Q13: - 참조성 데이터로 자동처리보다는 정책데이터를 구조화하고 해당 데이터를 입력/관리 할수 있는 페이지 구성이 적합하다고 판단됨
A14: R11 | B14: 백신 접종률(지역별) | C14: 역학 데이터 | E14: =VLOOKUP($D14,데이터소스!$A$3:$F$20,2, FALSE) -> #N/A | F14: =VLOOKUP($D14,데이터소스!$A$3:$F$20,3, FALSE) -> #N/A | G14: =VLOOKUP($D14,데이터소스!$A$3:$F$20,4, FALSE) -> #N/A | H14: =VLOOKUP($D14,데이터소스!$A$3:$F$20,5, FALSE) -> #N/A | I14: =VLOOKUP($D14,데이터소스!$A$3:$F$20,6, FALSE) -> #N/A | J14: 공공데이터포털(data.go.kr) | K14: 질병관리청 _코로나19 예방접종 통계 현황 | L14: - 참고) 질병관리청 _코로나19 예방접종 통계 현황: https://www.data.go.kr/data/15131145/fileData.do?recommendDataYn=Y - 전국 시도별 , 일자별 코로나19 예방접종 1차,2차,3차 접종률 제공 | M14: 최영준 | N14: 박성식 | O14: - 1차 검토의견과 동일 - 참고) 소아 예방접종률: https://kosis.kr/statHtml/statHtml.do?orgId=177&tblId=DT_11793N_163&conn_path=I2 - 참고) 시군구별 연도별 인플루엔자 접종률: https://kosis.kr/statHtml/statHtml.do?orgId=101&tblId=DT_1YL202103E&conn_path=I2 | P14: 초록색으로 수정 필요 필수데이터이므로 추가 확보할 수 있는 방안 검토 요청 오픈데이터 미확인 의미? 코로나 통계현황(xlsx)로 제공한다고 명시 -> 오픈데이터 미확인의 의미 | Q14: - 초록색으로 수정함 - 추가 데이터 소스는 확인 필요
A15: R12 | B15: 백신효과 및 내성 데이터 | E15: =VLOOKUP($D15,데이터소스!$A$3:$F$20,2, FALSE) -> #N/A | F15: =VLOOKUP($D15,데이터소스!$A$3:$F$20,3, FALSE) -> #N/A | G15: =VLOOKUP($D15,데이터소스!$A$3:$F$20,4, FALSE) -> #N/A | H15: =VLOOKUP($D15,데이터소스!$A$3:$F$20,5, FALSE) -> #N/A | I15: =VLOOKUP($D15,데이터소스!$A$3:$F$20,6, FALSE) -> #N/A | L15: - 감염병 관련 데이터 미확인 | M15: 최영준 | N15: 박성식 | O15: - 구조화된 개방 데이터 미확인 - 참고) 질병관리청 예방접종 효과 평가: https://www.phwr.org/journal/view.html?pn=search&uid=192&vmd=Full | P15: 초록색 수정 필수데이터이므로 확보할 수 있는 방안 검토 요청 | Q15: - 참조성 데이터로 자동처리보다는 정책데이터를 구조화하고 해당 데이터를 입력/관리 할수 있는 페이지 구성이 적합하다고 판단됨
A16: R13 | B16: 병상 가동률 | C16: 의료자원 데이터 | D16: DS-0402 | E16: =VLOOKUP($D16,데이터소스!$A$3:$F$20,2, FALSE) -> 중앙응급의료센터(NEMC) | F16: =VLOOKUP($D16,데이터소스!$A$3:$F$20,3, FALSE) -> 응급의료모니터링시스템 | G16: =VLOOKUP($D16,데이터소스!$A$3:$F$20,4, FALSE) -> https://dw.nemc.or.kr/nemcMonitoring/mainmgr/Main.do | H16: =VLOOKUP($D16,데이터소스!$A$3:$F$20,5, FALSE) -> 포털 | I16: =VLOOKUP($D16,데이터소스!$A$3:$F$20,6, FALSE) -> 60분 | J16: 국립중앙의료원(NMC) | K16: 응급의료모니터링시스템 | L16: - Open API, 개방데이터 형태로는 미확인 - 관련 실시간 통계정보 포털서비스로 가시화 제공중 | M16: 최영준 | N16: 박성식 | O16: - 1차 검토의견과 동일
A17: R14 | B17: 병상점유율 및 회전율 | C17: 의료자원 데이터 | D17: DS-0402 | E17: =VLOOKUP($D17,데이터소스!$A$3:$F$20,2, FALSE) -> 중앙응급의료센터(NEMC) | F17: =VLOOKUP($D17,데이터소스!$A$3:$F$20,3, FALSE) -> 응급의료모니터링시스템 | G17: =VLOOKUP($D17,데이터소스!$A$3:$F$20,4, FALSE) -> https://dw.nemc.or.kr/nemcMonitoring/mainmgr/Main.do | H17: =VLOOKUP($D17,데이터소스!$A$3:$F$20,5, FALSE) -> 포털 | I17: =VLOOKUP($D17,데이터소스!$A$3:$F$20,6, FALSE) -> 60분 | J17: 국립중앙의료원(NMC) | K17: 응급의료모니터링시스템 | L17: - 응급실, 입원병상 - 현재 데이터만 확인 가능 | M17: 박성식 | N17: 박성식 | O17: - 1차 검토의견과 동일
A18: R15 | B18: 병원 방문 환자 수 | C18: 사회·행태 데이터 | E18: =VLOOKUP($D18,데이터소스!$A$3:$F$20,2, FALSE) -> #N/A | F18: =VLOOKUP($D18,데이터소스!$A$3:$F$20,3, FALSE) -> #N/A | G18: =VLOOKUP($D18,데이터소스!$A$3:$F$20,4, FALSE) -> #N/A | H18: =VLOOKUP($D18,데이터소스!$A$3:$F$20,5, FALSE) -> #N/A | I18: =VLOOKUP($D18,데이터소스!$A$3:$F$20,6, FALSE) -> #N/A | K18: 의료정보-연구,통계-통계자료실-건강보험통계연보 | L18: - 월별 지역별 병원 방문 환자 수 제공 - 개별 병원에 대한 정보는 제공하지 않음 | M18: 박성식 | N18: 박성식 | O18: - 1차 검토의견과 동일
A19: R16 | B19: 병원별 감염병 대응단계 | C19: 공중보건 정책 데이터 | E19: =VLOOKUP($D19,데이터소스!$A$3:$F$20,2, FALSE) -> #N/A | F19: =VLOOKUP($D19,데이터소스!$A$3:$F$20,3, FALSE) -> #N/A | G19: =VLOOKUP($D19,데이터소스!$A$3:$F$20,4, FALSE) -> #N/A | H19: =VLOOKUP($D19,데이터소스!$A$3:$F$20,5, FALSE) -> #N/A | I19: =VLOOKUP($D19,데이터소스!$A$3:$F$20,6, FALSE) -> #N/A | L19: - 구조화된 개방 데이터 미확인 | M19: 박성식 | N19: 박성식 | O19: - 1차 검토의견과 동일
A20: R17 | B20: 병원별 장비 보유 | C20: 의료자원 데이터 | D20: DS-0401 | E20: =VLOOKUP($D20,데이터소스!$A$3:$F$20,2, FALSE) -> 중앙응급의료센터(NEMC) | F20: =VLOOKUP($D20,데이터소스!$A$3:$F$20,3, FALSE) -> 종합상황판 | G20: =VLOOKUP($D20,데이터소스!$A$3:$F$20,4, FALSE) -> https://portal.nemc.or.kr:444/medi_info/dashboards/dash_total_emer_org_popup_for_egen.do | H20: =VLOOKUP($D20,데이터소스!$A$3:$F$20,5, FALSE) -> 포털 | I20: =VLOOKUP($D20,데이터소스!$A$3:$F$20,6, FALSE) -> 60분 | J20: 중앙응급의료센터(NEMC) | K20: 종합현황판 | L20: - 병원 별 보유 장비 현황 - 현재 데이터만 확인 가능 | M20: 박성식 | N20: 박성식 | O20: - 1차 검토의견과 동일
A21: R18 | B21: 사망률 및 합병증 발생률 | C21: 역학 데이터 | E21: =VLOOKUP($D21,데이터소스!$A$3:$F$20,2, FALSE) -> #N/A | F21: =VLOOKUP($D21,데이터소스!$A$3:$F$20,3, FALSE) -> #N/A | G21: =VLOOKUP($D21,데이터소스!$A$3:$F$20,4, FALSE) -> #N/A | H21: =VLOOKUP($D21,데이터소스!$A$3:$F$20,5, FALSE) -> #N/A | I21: =VLOOKUP($D21,데이터소스!$A$3:$F$20,6, FALSE) -> #N/A | L21: - 구조화된 개방 데이터 미확인 | M21: 박성식 | N21: 박성식 | O21: - 1차 검토의견과 동일 | P21: 사망률 통계데이터 필수이므로 확보 방안 검토 요청 | Q21: - 감염병 포털에 감염병별 사망자수는 확인됨 - 코로나의 경우는 감염병 포털에서 별도 파일(xls)로 제공중임을 확인함 - 사망률 관련해서는 처리 하거나, 별도의 관련 데이터 소스 확인 필요
A22: R19 | B22: 신규바이러스 발생여부 | E22: =VLOOKUP($D22,데이터소스!$A$3:$F$20,2, FALSE) -> #N/A | F22: =VLOOKUP($D22,데이터소스!$A$3:$F$20,3, FALSE) -> #N/A | G22: =VLOOKUP($D22,데이터소스!$A$3:$F$20,4, FALSE) -> #N/A | H22: =VLOOKUP($D22,데이터소스!$A$3:$F$20,5, FALSE) -> #N/A | I22: =VLOOKUP($D22,데이터소스!$A$3:$F$20,6, FALSE) -> #N/A | L22: - 구조화된 개방 데이터 미확인 | M22: 박성식 | N22: 최영준
A23: R20 | B23: 연령대별/성별 감염률 | C23: 역학 데이터 | D23: DS-0101 | E23: =VLOOKUP($D23,데이터소스!$A$3:$F$20,2, FALSE) -> 질병관리청(KDCA) | F23: =VLOOKUP($D23,데이터소스!$A$3:$F$20,3, FALSE) -> 감염병 포털-전수감시 감염병(기간별 통계) | G23: =VLOOKUP($D23,데이터소스!$A$3:$F$20,4, FALSE) -> https://dportal.kdca.go.kr/pot/is/summaryEDW.do | H23: =VLOOKUP($D23,데이터소스!$A$3:$F$20,5, FALSE) -> 파일(xml, csv) | I23: =VLOOKUP($D23,데이터소스!$A$3:$F$20,6, FALSE) -> 년, 월, 주 | J23: 질병관리청(KDCA) | K23: 감염병 포털-전수감시 감염병(기간별 통계) | L23: - 1/2/3급 감염병 대상, 기간은 년도/월별 주간 발행통계/지역별 발생통계 - 일별 발생 통계 데이터 없음 | M23: 박성식 | N23: 최영준 | O23: - 1차 검토의견과 동일 | P23: (J5내용 참고) 코로나/인플루엔자 등 과제가 타겟팅하는 감염병 데이터 적재되어 있는지 | Q23: - 인플루엔자의 경우 표본감시감염병에 연령대별로는 제공하고 있음 - 코로나의 경우는 감염병 포털에서 별도 파일(xls)로 제공중임을 확인함
A24: R21 | B24: 온습도, PM2.5, CO2 | C24: 환경 데이터 | D24: DS-0901 | E24: =VLOOKUP($D24,데이터소스!$A$3:$F$20,2, FALSE) -> 구글 | F24: =VLOOKUP($D24,데이터소스!$A$3:$F$20,3, FALSE) -> 구글 트렌드 | G24: =VLOOKUP($D24,데이터소스!$A$3:$F$20,4, FALSE) -> https://trends.google.co.kr/trends/ | H24: =VLOOKUP($D24,데이터소스!$A$3:$F$20,5, FALSE) -> 포털 | I24: =VLOOKUP($D24,데이터소스!$A$3:$F$20,6, FALSE) -> 1시간,4시간,7일 등 | J24: 구글 | K24: 구글 트렌드 | L24: - 정확한 수치가 아닌 비율적으로 제공 - (비공식)라이브러리 사용 | M24: 박성식 | N24: 최영준 | O24: - 1차 검토의견과 동일 | P24: *환경데이터와 데이터 항목 구분 요청 *환경데이터의 경우, 지역별 대기질 데이터 확보 필요 (예: 에어코리아, 기상청 등) *인플루엔자 관련 검색 트렌드-방역 정책 등과 연계하여 SNS트렌드 데이터 확보 제안 *구글트렌드뿐 아니라 트위터, 네이버 등 타 요소 활용도 검토 요청 | Q24: - 에어코리아 제공데이터는 공공데이터 포털을 통해 서비스중이라 수집 처리 가능함 - 수집대상 범위가 방대해 주기적 모든데이터를 수집/중복 저장하는 문제는 협의 필요(공공데이터 포털도 운영계정의 일별 제약은 있음) - 통상 서비스에서는 필요시점의 필요지역데이터를 수집하는 방식임
A25: R22 | B25: 인플루엔자 관련 검색 트렌드 | C25: 사회·행태 데이터 | D25: DS-0901 | E25: =VLOOKUP($D25,데이터소스!$A$3:$F$20,2, FALSE) -> 구글 | F25: =VLOOKUP($D25,데이터소스!$A$3:$F$20,3, FALSE) -> 구글 트렌드 | G25: =VLOOKUP($D25,데이터소스!$A$3:$F$20,4, FALSE) -> https://trends.google.co.kr/trends/ | H25: =VLOOKUP($D25,데이터소스!$A$3:$F$20,5, FALSE) -> 포털 | I25: =VLOOKUP($D25,데이터소스!$A$3:$F$20,6, FALSE) -> 1시간,4시간,7일 등 | J25: 구글 | K25: 구글 트렌드 | L25: - 정확한 수치가 아닌 비율적으로 제공 - (비공식)라이브러리 사용 | M25: 박성식 | N25: 최영준 | O25: - 1차 검토의견과 동일 | P25: *구글트렌드뿐 아니라 트위터, 네이버 등 타 요소 활용도 검토 요청 | Q25: - 추가 검토중(네이버)
A26: R23 | B26: 응급 이송 후 전원 후속 치료 가능여부 | C26: 진료지원 인프라 데이터 | E26: =VLOOKUP($D26,데이터소스!$A$3:$F$20,2, FALSE) -> #N/A | F26: =VLOOKUP($D26,데이터소스!$A$3:$F$20,3, FALSE) -> #N/A | G26: =VLOOKUP($D26,데이터소스!$A$3:$F$20,4, FALSE) -> #N/A | H26: =VLOOKUP($D26,데이터소스!$A$3:$F$20,5, FALSE) -> #N/A | I26: =VLOOKUP($D26,데이터소스!$A$3:$F$20,6, FALSE) -> #N/A | L26: - 구조화된 개방 데이터 미확인 | M26: 박성식 | N26: 최영준 | O26: - 1차 검토의견과 동일
A27: R24 | B27: 의료진 근무현황 | C27: 진료지원 인프라 데이터 | D27: DS-0402 | E27: =VLOOKUP($D27,데이터소스!$A$3:$F$20,2, FALSE) -> 중앙응급의료센터(NEMC) | F27: =VLOOKUP($D27,데이터소스!$A$3:$F$20,3, FALSE) -> 응급의료모니터링시스템 | G27: =VLOOKUP($D27,데이터소스!$A$3:$F$20,4, FALSE) -> https://dw.nemc.or.kr/nemcMonitoring/mainmgr/Main.do | H27: =VLOOKUP($D27,데이터소스!$A$3:$F$20,5, FALSE) -> 포털 | I27: =VLOOKUP($D27,데이터소스!$A$3:$F$20,6, FALSE) -> 60분 | J27: 중앙응급의료센터(NEMC) | K27: 응급의료모니터링시스템 | L27: - 구조화된 개방 데이터 미확인 - 관련 의료기관 소속 사용자 접근으로 제한됨 | M27: 박성식 | N27: 최영준 | O27: - 1차 검토의견과 동일
A28: R25 | B28: 의료진 수급상황 | C28: 진료지원 인프라 데이터 | D28: DS-0202 | E28: =VLOOKUP($D28,데이터소스!$A$3:$F$20,2, FALSE) -> 건강보험심사평가원(HIRA) | F28: =VLOOKUP($D28,데이터소스!$A$3:$F$20,3, FALSE) -> 의료정보-연구,통계-통계자료실-건강보험통계연보 | G28: =VLOOKUP($D28,데이터소스!$A$3:$F$20,4, FALSE) -> https://www.hira.or.kr/bbsDummy.do?pgmid=HIRAA020045020000 | H28: =VLOOKUP($D28,데이터소스!$A$3:$F$20,5, FALSE) -> 파일 | I28: =VLOOKUP($D28,데이터소스!$A$3:$F$20,6, FALSE) -> 년 | J28: 건강보험심사평가원(HIRA) | K28: 의료통계정보-의료자원 통계-인력 현황-지역별 종별 의료인력I(의사 등) | L28: - 통계 이력데이터로 제공 확인됨 - 시군구별 분기별 요양종별 인력현황 | M28: 박성식 | N28: 최영준 | O28: - 1차 검토의견과 동일
A29: R26 | B29: 이동패턴 | C29: 역학 데이터 | D29: DS-0601 | E29: =VLOOKUP($D29,데이터소스!$A$3:$F$20,2, FALSE) -> 서울시 열린데이터광장 | F29: =VLOOKUP($D29,데이터소스!$A$3:$F$20,3, FALSE) -> 수도권 생활이동 (연령별, 출발-도착지 기준)-내국인 | G29: =VLOOKUP($D29,데이터소스!$A$3:$F$20,4, FALSE) -> https://data.seoul.go.kr/dataList/OA-22299/F/1/datasetView.do | H29: =VLOOKUP($D29,데이터소스!$A$3:$F$20,5, FALSE) -> OpenAPI | I29: =VLOOKUP($D29,데이터소스!$A$3:$F$20,6, FALSE) -> 일 | J29: 서울시 열린데이터광장 | K29: 수도권 생활이동 (연령별, 출발-도착지 기준)-내국인 | L29: - 서울시 한정 - 이동데이터 구조등이 다양 - 역학조사지원시스템(EISS) 연계 가능여부 확인 필요 | M29: 이준욱 | N29: 최영준 | O29: - 1차 검토의견과 동일 | P29: 역조시스템 사용 안할 예정이므로 후순위 | Q29: 불가함 | R29: 확보하지 못하는 역학데이터는 SNS등 검색 키워드 데이터로 보완할 수는 없는지?
A30: R27 | B30: 이송수단(구급차, 헬기, 응급의료팀 동반) | C30: 진료지원 인프라 데이터 | D30: DS-0402 | E30: =VLOOKUP($D30,데이터소스!$A$3:$F$20,2, FALSE) -> 중앙응급의료센터(NEMC) | F30: =VLOOKUP($D30,데이터소스!$A$3:$F$20,3, FALSE) -> 응급의료모니터링시스템 | G30: =VLOOKUP($D30,데이터소스!$A$3:$F$20,4, FALSE) -> https://dw.nemc.or.kr/nemcMonitoring/mainmgr/Main.do | H30: =VLOOKUP($D30,데이터소스!$A$3:$F$20,5, FALSE) -> 포털 | I30: =VLOOKUP($D30,데이터소스!$A$3:$F$20,6, FALSE) -> 60분 | J30: 중앙응급의료센터(NEMC) | K30: 응급의료모니터링시스템 | L30: - 감염병 특정해서는 제공 정보 미확인 - 공공데이터 포탈에 소방청_구급활동정보병원제공_환자이송현황은 있으나 연관데이터는 미식별됨 | M30: 이준욱 | N30: 최영준 | O30: - 1차 검토의견과 동일
A31: R28 | B31: 인구밀도 | C31: 사회·행태 데이터 | D31: DS-0301 | E31: =VLOOKUP($D31,데이터소스!$A$3:$F$20,2, FALSE) -> 국가통계포털(KOSIS) | F31: =VLOOKUP($D31,데이터소스!$A$3:$F$20,3, FALSE) -> 성별 및 연령별 인구와 인구밀도 | G31: =VLOOKUP($D31,데이터소스!$A$3:$F$20,4, FALSE) -> https://kosis.kr/openapi/Param/statisticsParameterData.do?method=getList&apiKey=YjhkNjhiMTM1YTU0ZjJlZGEzNTU2MmYxYTMwZGM0YzY=&itmId=00+&objL1=ALL&objL2=ALL&objL3=&objL4=&objL5=&objL6=&objL7=&objL8=&format=json&jsonVD=Y&prdSe=Y&newEstPrdCnt=3&orgId=110&tblId=DT_11001N_2013_A001 | H31: =VLOOKUP($D31,데이터소스!$A$3:$F$20,5, FALSE) -> OpenAPI | I31: =VLOOKUP($D31,데이터소스!$A$3:$F$20,6, FALSE) -> 년 | J31: 국가통계포털(KOSIS) | K31: 성 및 연령별 인구와 인구밀도 | M31: 이준욱 | N31: 최영준 | O31: - 1차 검토의견과 동일
A32: R29 | B32: 인플루엔자 변종 및 유형별 감염률 | C32: 역학 데이터 | E32: =VLOOKUP($D32,데이터소스!$A$3:$F$20,2, FALSE) -> #N/A | F32: =VLOOKUP($D32,데이터소스!$A$3:$F$20,3, FALSE) -> #N/A | G32: =VLOOKUP($D32,데이터소스!$A$3:$F$20,4, FALSE) -> #N/A | H32: =VLOOKUP($D32,데이터소스!$A$3:$F$20,5, FALSE) -> #N/A | I32: =VLOOKUP($D32,데이터소스!$A$3:$F$20,6, FALSE) -> #N/A | L32: 공공데이터 포털에 '국민건강보험공단_감염성질환(인플루엔자) 의료이용정보 제공'서비스는 있으나 연관데이터 비식별됨 | M32: 이준욱 | N32: 최영준 | O32: - 1차 검토의견과 동일 | P32: 필수 데이터이므로 데이터 얻을 수 있는 대안책 추가 제시 혹은 WHO FluNet 활용 방안 검토 요청 | Q32: '- 제공되거나 알려진 데이터소스 찾는 방안외에 별도 대안책은 없음 - WHO FlueNet의 수집/적재는 가능하나, 활용대상인지 여부 확정 요망
A33: R30 | B33: 중증 환자 비율 | C33: 역학 데이터 | E33: =VLOOKUP($D33,데이터소스!$A$3:$F$20,2, FALSE) -> #N/A | F33: =VLOOKUP($D33,데이터소스!$A$3:$F$20,3, FALSE) -> #N/A | G33: =VLOOKUP($D33,데이터소스!$A$3:$F$20,4, FALSE) -> #N/A | H33: =VLOOKUP($D33,데이터소스!$A$3:$F$20,5, FALSE) -> #N/A | I33: =VLOOKUP($D33,데이터소스!$A$3:$F$20,6, FALSE) -> #N/A | M33: 이준욱 | N33: 최영준 | O33: - 1차 검토의견과 동일 | P33: 병원데이터 활용 | Q33: - 분석 및 데이터 모델링을 위해 EMR 데이터 샘플등의 자료 제공 필요
A34: R31 | B34: 중증환자 및 사망률 | C34: 역학 데이터 | D34: DS-0503 | E34: =VLOOKUP($D34,데이터소스!$A$3:$F$20,2, FALSE) -> 공공데이터포털(data.go.kr) | F34: =VLOOKUP($D34,데이터소스!$A$3:$F$20,3, FALSE) -> 보건복지부_제1군 감염병 발생 수 및 사망자 수 | G34: =VLOOKUP($D34,데이터소스!$A$3:$F$20,4, FALSE) -> https://www.data.go.kr/data/15128046/fileData.do | H34: =VLOOKUP($D34,데이터소스!$A$3:$F$20,5, FALSE) -> 파일 | I34: =VLOOKUP($D34,데이터소스!$A$3:$F$20,6, FALSE) -> 년 | J34: 공공데이터포털(data.go.kr) | K34: 보건복지부_제1군 감염병 발생 수 및 사망자 수 | L34: - 1/2/3/4군별 발생율과 사망자 수(5년기준), 최근 ~2019년까지 | M34: 이준욱 | N34: 최영준 | O34: - 1차 검토의견과 동일
A35: R32 | B35: 지역별 감염분포 | C35: 역학 데이터 | D35: DS-0102 | E35: =VLOOKUP($D35,데이터소스!$A$3:$F$20,2, FALSE) -> 질병관리청(KDCA) | F35: =VLOOKUP($D35,데이터소스!$A$3:$F$20,3, FALSE) -> 지역별 감염병 발생현황(질병별 연도별 월별 기간별_ 통계) | G35: =VLOOKUP($D35,데이터소스!$A$3:$F$20,4, FALSE) -> https://dportal.kdca.go.kr/pot/is/summaryRgin.do | H35: =VLOOKUP($D35,데이터소스!$A$3:$F$20,5, FALSE) -> 포털 | I35: =VLOOKUP($D35,데이터소스!$A$3:$F$20,6, FALSE) -> 년 | J35: 질병관리청(KDCA) | K35: 지역별 감염병 발생현황(질병별 연도별 월별 기간별_ 통계) | L35: - 감염병 포털서비스를 통해 감염병 지역별 발생 현황 통계 정보(연간발생) 제공중 | M35: 이준욱 | N35: 최영준 | O35: - 1차 검토의견과 동일
A36: R33 | B36: 지역별 병원 수용능력 | C36: 의료자원 데이터 | D36: DS-0501 | E36: =VLOOKUP($D36,데이터소스!$A$3:$F$20,2, FALSE) -> 공공데이터포털(data.go.kr) | F36: =VLOOKUP($D36,데이터소스!$A$3:$F$20,3, FALSE) -> 전국 응급의료기관 정보 조회 서비스 | G36: =VLOOKUP($D36,데이터소스!$A$3:$F$20,4, FALSE) -> https://www.data.go.kr/data/15000563/openapi.do | H36: =VLOOKUP($D36,데이터소스!$A$3:$F$20,5, FALSE) -> OpenAPI | I36: =VLOOKUP($D36,데이터소스!$A$3:$F$20,6, FALSE) -> 일 | J36: 공공데이터포털(data.go.kr) | K36: 전국 응급의료기관 정보 조회 서비스 | L36: -전국 응급의료기관 정보 조회 서비스 | M36: 이준욱 | N36: 최영준 | O36: - 1차 검토의견과 동일
A37: R34 | B37: 치료제 및 백신개발여부 | C37: 의약품 및 처방 데이터 | D37: DS-0504 | E37: =VLOOKUP($D37,데이터소스!$A$3:$F$20,2, FALSE) -> 공공데이터포털(data.go.kr) | F37: =VLOOKUP($D37,데이터소스!$A$3:$F$20,3, FALSE) -> 식품의약품안전처_감염병백신의약품 제품정보 | G37: =VLOOKUP($D37,데이터소스!$A$3:$F$20,4, FALSE) -> https://www.data.go.kr/data/15084885/openapi.do | H37: =VLOOKUP($D37,데이터소스!$A$3:$F$20,5, FALSE) -> OpenAPI | I37: =VLOOKUP($D37,데이터소스!$A$3:$F$20,6, FALSE) -> 일 | J37: 공공데이터포털(data.go.kr) | K37: 식품의약품안전처_감염병백신의약품 제품정보 | L37: '- 감염병 관련 치료제 정보에 대해서 확인됨 - 임상시험 데이터, 시판 후 조사 데이터, 학술 연구 결과 등 다양한 출처를 통해 확인 필요 | M37: 이준욱 | N37: 최영준 | O37: - 1차 검토의견과 동일 | P37: 초록색으로 수정 필요 / 필수데이터 치료제 정보 데이터셋 구성 필수 기저질환여부 또한 중증도 모델에서 활용되므로 빈도 높은 기저질환에 관련된 의약품 정보 또한 확보하는 것 필요해보임 - 의약품 정보 라이브러리 구성 규모 논의 필요 | Q37: - 다양한 데이터 출처 및 형식으로 존재하므로, 자동처리에 제약이 크고 비효율적임 - 필요 데이터셋에 대한 요구사항 기반 모델링후 후처리하여 데이터 입력/관리하는 페이지 구성하는 것이 필요함
A38: R35 | B38: 치료제 처방데이터 | C38: 의약품 및 처방 데이터 | E38: =VLOOKUP($D38,데이터소스!$A$3:$F$20,2, FALSE) -> #N/A | F38: =VLOOKUP($D38,데이터소스!$A$3:$F$20,3, FALSE) -> #N/A | G38: =VLOOKUP($D38,데이터소스!$A$3:$F$20,4, FALSE) -> #N/A | H38: =VLOOKUP($D38,데이터소스!$A$3:$F$20,5, FALSE) -> #N/A | I38: =VLOOKUP($D38,데이터소스!$A$3:$F$20,6, FALSE) -> #N/A | L38: - 건강보험심사평가원(HIRA)에서 공개한 통계데이터 수준 - 개인처방정보는 정보 접근 어려움 | M38: 이준욱 | N38: 최영준 | O38: - 1차 검토의견과 동일 | P38: 통계데이터 확보 요청 | Q38: - 확인중
A39: R35 | B39: 확진자 수 및 발생률(일별, 주별, 지역별) | C39: 역학 데이터 | D39: DS-0102 | E39: =VLOOKUP($D39,데이터소스!$A$3:$F$20,2, FALSE) -> 질병관리청(KDCA) | F39: =VLOOKUP($D39,데이터소스!$A$3:$F$20,3, FALSE) -> 지역별 감염병 발생현황(질병별 연도별 월별 기간별_ 통계) | G39: =VLOOKUP($D39,데이터소스!$A$3:$F$20,4, FALSE) -> https://dportal.kdca.go.kr/pot/is/summaryRgin.do | H39: =VLOOKUP($D39,데이터소스!$A$3:$F$20,5, FALSE) -> 포털 | I39: =VLOOKUP($D39,데이터소스!$A$3:$F$20,6, FALSE) -> 년 | J39: 질병관리청(KDCA) | K39: 감염병 포털-전수감시 감염병(기간별 통계) | L39: - 1/2/3급 감염병 대상, 기간은 년도/월별 주간 발행통계/지역별 발생통계 - 일별 발생 통계 데이터 없음 | M39: 이준욱 | N39: 최영준 | O39: - 1차 검토의견과 동일 | P39: KCDC 에서 1~3급 상 인플루엔자 데이터 확인요청 | Q39: - 판단에 한계가 있으므로, 함꼐 확인 요망
A40: R36 | B40: 환자 이송 시 위험요인(예: 산소치료유지필요, 응급조치 가능여부) | C40: 진료지원 인프라 데이터 | D40: DS-0402 | E40: =VLOOKUP($D40,데이터소스!$A$3:$F$20,2, FALSE) -> 중앙응급의료센터(NEMC) | F40: =VLOOKUP($D40,데이터소스!$A$3:$F$20,3, FALSE) -> 응급의료모니터링시스템 | G40: =VLOOKUP($D40,데이터소스!$A$3:$F$20,4, FALSE) -> https://dw.nemc.or.kr/nemcMonitoring/mainmgr/Main.do | H40: =VLOOKUP($D40,데이터소스!$A$3:$F$20,5, FALSE) -> 포털 | I40: =VLOOKUP($D40,데이터소스!$A$3:$F$20,6, FALSE) -> 60분 | J40: 중앙응급의료센터(NEMC) | K40: 응급의료모니터링시스템 | L40: - 관련 통계데이터 미확인 - 참고(코로나19 응급이송체계 변화) : https://www.ggpi.or.kr/images/issue/issue21.pdf | M40: 이준욱 | N40: 최영준 | O40: - 1차 검토의견과 동일
...

Sheet 데이터소스
A2: ID | B2: 제공기관명 | C2: 서비스명 | D2: 서비스URL | E2: 제공방식 | F2: 제공 주기 | G2: 의견 | H2: 아이브랩 의견
A3: DS-0101 | B3: 질병관리청(KDCA) | C3: 감염병 포털-전수감시 감염병(기간별 통계) | D3: https://dportal.kdca.go.kr/pot/is/summaryEDW.do | E3: 파일(xml, csv) | F3: 년, 월, 주 | G3: 동물인플루엔자/신종인플루엔자 모두 사이트 내에 적재된 통계데이터가 없음 | H3: 별도 데이터 출처 제공 또는 확인 필요
A4: DS-0102 | B4: 질병관리청(KDCA) | C4: 지역별 감염병 발생현황(질병별 연도별 월별 기간별_ 통계) | D4: https://dportal.kdca.go.kr/pot/is/summaryRgin.do | E4: 포털 | F4: 년
A5: DS-0201 | B5: 건강보험심사평가원(HIRA) | C5: 의료통계정보-의료자원 통계-인력 현황-지역별 종별 의료인력I(의사 등) | D5: https://opendata.hira.or.kr/op/opc/olapHumanResourceStatInfoTab1.do | E5: 포털 | F5: 분기
A6: DS-0202 | B6: 건강보험심사평가원(HIRA) | C6: 의료정보-연구,통계-통계자료실-건강보험통계연보 | D6: https://www.hira.or.kr/bbsDummy.do?pgmid=HIRAA020045020000 | E6: 파일 | F6: 년
A7: DS-0301 | B7: 국가통계포털(KOSIS) | C7: 성별 및 연령별 인구와 인구밀도 | D7: https://kosis.kr/openapi/Param/statisticsParameterData.do?method=getList&apiKey=YjhkNjhiMTM1YTU0ZjJlZGEzNTU2MmYxYTMwZGM0YzY=&itmId=00+&objL1=ALL&objL2=ALL&objL3=&objL4=&objL5=&objL6=&objL7=&objL8=&format=json&jsonVD=Y&prdSe=Y&newEstPrdCnt=3&orgId=110&tblId=DT_11001N_2013_A001 | E7: OpenAPI | F7: 년
A8: DS-0401 | B8: 중앙응급의료센터(NEMC) | C8: 종합상황판 | D8: https://portal.nemc.or.kr:444/medi_info/dashboards/dash_total_emer_org_popup_for_egen.do | E8: 포털 | F8: 60분 | G8: 해당 url이 접근 권한이 필요한 인트라넷인걸로 보임. 정상적인 경로로 권한 얻어 정보를 취득할 것인지 비정상적인 경로로 해당 정보를 접근할 것이지 논의 필요. | H8: -https://www.nmc.or.kr/nmc/contents/emergency_synthesis_sign 페이지를 통해 제공중이므로 접근 경로가 비정상적이지는 않다고 판단함
A9: DS-0402 | B9: 중앙응급의료센터(NEMC) | C9: 응급의료모니터링시스템 | D9: https://dw.nemc.or.kr/nemcMonitoring/mainmgr/Main.do | E9: 포털 | F9: 60분
A10: DS-0501 | B10: 공공데이터포털(data.go.kr) | C10: 전국 응급의료기관 정보 조회 서비스 | D10: https://www.data.go.kr/data/15000563/openapi.do | E10: OpenAPI | F10: 일
A11: DS-0502 | B11: 공공데이터포털(data.go.kr) | C11: 건강보험심사평가원_의료기관별 감염병 및 중증환자 치료시설 현황 | D11: https://www.data.go.kr/data/15085951/fileData.do | E11: 파일 | F11: 비정기
A12: DS-0503 | B12: 공공데이터포털(data.go.kr) | C12: 보건복지부_제1군 감염병 발생 수 및 사망자 수 | D12: https://www.data.go.kr/data/15128046/fileData.do | E12: 파일 | F12: 년
A13: DS-0504 | B13: 공공데이터포털(data.go.kr) | C13: 식품의약품안전처_감염병백신의약품 제품정보 | D13: https://www.data.go.kr/data/15084885/openapi.do | E13: OpenAPI | F13: 일
A14: DS-0505 | B14: 공공데이터포털(data.go.kr) | C14: 질병관리청_코로나19 예방접종 통계 현황 | D14: https://www.data.go.kr/data/15131145/fileData.do?recommendDataYn=Y | E14: 파일 | F14: 단일 파일
A15: DS-0601 | B15: 서울시 열린데이터광장 | C15: 수도권 생활이동 (연령별, 출발-도착지 기준)-내국인 | D15: https://data.seoul.go.kr/dataList/OA-22299/F/1/datasetView.do | E15: OpenAPI | F15: 일
A16: DS-0701 | B16: 응급의료통계 포털 | C16: 응급의료정보망, 중증응급질환관련 통계 | D16: https://e-medis.nemc.or.kr/portal/stat/easyStatPage.do | E16: 포털 | F16: 년
A17: DS-0801 | B17: 소방안전 빅데이터 플랫폼 | C17: 질병 구급출동 현황 | D17: https://www.bigdata-119.kr/goods/goodsInfo?goods_id=202302000065 | F17: 비정기
A18: DS-0901 | B18: 구글 | C18: 구글 트렌드 | D18: https://trends.google.co.kr/trends/ | E18: 포털 | F18: 1시간,4시간,7일 등
A19: DS-1001 | B19: 한국도로공사 | C19: 실시간 전국 교통량 | D19: https://data.ex.co.kr/openapi/basicinfo/openApiInfoM?apiId=0102&serviceType=&keyWord=&searchDayFrom=undefined&searchDayTo=undefined&CATEGORY=TR&GROUP_TR=&sId=174 | E19: OpenAPI | F19: 1시간,15분,5분
A20: DS-1101 | B20: 경기데이터드림 | C20: 경기도 구급차 및 구급대원 현황 | D20: https://data.gg.go.kr/portal/data/service/selectServicePage.do?page=1&rows=10&sortColumn=&sortDirection=&infId=JE55Y365432IZR9CT9R926586107&infSeq=2 | E20: OpenAPI | F20: 년

Sheet 자동수집데이터리스트
A1: ID | B1: 제공기관명 | C1: 서비스명 | D1: 서비스URL | E1: 서비스 요청 URL | F1: 제공방식 | G1: 수집데이터형식 | H1: 제공 주기 | I1: JBNU 서버 검증 | J1: 개발서버 검증 | K1: 서비스현황 | L1: 크롤링여부 | M1: 크롤링개선여부 | N1: 과거 데이터 수집 가능 여부 | O1: 수집여부
A2: ds_0101 | B2: 질병관리청 감염병 포털 | C2: 인플루엔자 의사환자 비율 | D2: https://dportal.kdca.go.kr/pot/is/st/fluON.do | E2: https://public.tableau.com/app/profile/kimjia/viz/_17530910022760/02ILI | F2: WEB | G2: CSV | H2: 7일 | I2: O | J2: O | K2: O | L2: O | M2: O | N2: 2017년 36주부터 | O2: O
A3: ds_0102 | B3: 질병관리청 감염병 포털 | C3: 인플루엔자 유행단계 | D3: https://dportal.kdca.go.kr/pot/is/st/fluON.do | E3: https://public.tableau.com/app/profile/kimjia/viz/_17530910022760/01 | F3: WEB | G3: CSV | H3: 7일 | I3: O | J3: O | K3: O | L3: O | M3: O | N3: X | O3: X
A4: ds_0103 | B4: 질병관리청 감염병 포털 | C4: 급성호흡기감염증 환자 중 인플루엔자 환자 수(ARI) | D4: https://dportal.kdca.go.kr/pot/is/st/fluON.do | E4: https://public.tableau.com/app/profile/kimjia/viz/_17530910022760/03ARI | F4: WEB | G4: CSV | H4: 7일 | I4: O | J4: O | K4: O | L4: O | M4: O | N4: 2017년 36주부터 | O4: O
A5: ds_0104 | B5: 질병관리청 감염병 포털 | C5: 중증급성호흡기감염증 환자 중 인플루엔자 환자 수(SARI) | D5: https://dportal.kdca.go.kr/pot/is/st/fluON.do | E5: https://public.tableau.com/app/profile/kimjia/viz/_17530910022760/04SARI | F5: WEB | G5: CSV | H5: 7일 | I5: O | J5: O | K5: O | L5: O | M5: O | N5: 2017년 36주부터 | O5: O
A6: ds_0105 | B6: 질병관리청 감염병 포털 | C6: 의원급 의료기관 인플루엔자 검출률(K-RISS)-아형별 | D6: https://dportal.kdca.go.kr/pot/is/st/fluON.do | E6: https://public.tableau.com/app/profile/kimjia/viz/_17530910022760/05_KRISS | F6: WEB | G6: CSV | H6: 7일 | I6: O | J6: O | K6: O | L6: O | M6: O | N6: 2017년 36주부터 | O6: O
A7: ds_0106 | B7: 질병관리청 감염병 포털 | C7: 의원급 의료기관 인플루엔자 검출률(K-RISS)-연령대별 | D7: https://dportal.kdca.go.kr/pot/is/st/fluON.do | E7: https://public.tableau.com/app/profile/kimjia/viz/_17530910022760/05_KRISS | F7: WEB | G7: CSV | H7: 7일 | I7: O | J7: O | K7: O | L7: O | M7: O | N7: 2017년 36주부터 | O7: O
A8: ds_0107 | B8: 질병관리청 감염병 포털 | C8: 검사기관 인플루엔자 검출률-아형별 | D8: https://dportal.kdca.go.kr/pot/is/st/fluON.do | E8: https://public.tableau.com/app/profile/kimjia/viz/_17530910022760/06LAB | F8: WEB | G8: CSV | H8: 7일 | I8: O | J8: O | K8: O | L8: O | M8: O | N8: 2024년 1주부터 | O8: O
A9: ds_0108 | B9: 질병관리청 감염병 포털 | C9: 검사기관 인플루엔자 검출률-연령대별 | D9: https://dportal.kdca.go.kr/pot/is/st/fluON.do | E9: https://public.tableau.com/app/profile/kimjia/viz/_17530910022760/06LAB | F9: WEB | G9: CSV | H9: 7일 | I9: O | J9: O | K9: O | L9: O | M9: O | N9: 2024년 1주부터 | O9: O
A10: ds_0109 | B10: 질병관리청 감염병 포털 | C10: 응급실 인플루엔자 환자 수(NEDIS) | D10: https://dportal.kdca.go.kr/pot/is/st/fluON.do | E10: https://public.tableau.com/app/profile/kimjia/viz/_17530910022760/07NEDIS | F10: WEB | G10: CSV | H10: 7일 | I10: O | J10: O | K10: O | L10: O | M10: O | N10: 2018년 36주부터 | O10: O
A11: ds_0110 | B11: 질병관리청 감염병 포털 | C11: 인플루엔자 예방접종률-어르신 | D11: https://dportal.kdca.go.kr/pot/is/st/fluON.do | E11: https://public.tableau.com/app/profile/kimjia/viz/_17530910022760/08VAC | F11: WEB | G11: CSV | H11: 7일 | I11: O | J11: O | K11: O | L11: O | M11: O | N11: 2017년 36주부터 | O11: O
A12: ds_0111 | B12: 질병관리청 감염병 포털 | C12: 인플루엔자 예방접종률-어린이 | D12: https://dportal.kdca.go.kr/pot/is/st/fluON.do | E12: https://public.tableau.com/app/profile/kimjia/viz/_17530910022760/08VAC | F12: WEB | G12: CSV | H12: 7일 | I12: O | J12: O | K12: O | L12: O | M12: O | N12: 2017년 36주부터 | O12: O
... A14: ds_0202 | B14: 보건의료빅데이터개방시스템 | C14: 질병 세분류(4단 상병) 통계-성별/연령5세구간별 | D14: https://opendata.hira.or.kr/op/opc/olap4thDsInfoTab2.do | E14: https://opendata.hira.or.kr/op/opc/olap4thDsInfoTab2.do | F14: WEB | G14: CSV | H14: 1개월 | I14: O | J14: O | K14: O | L14: O | M14: O | N14: 2010년 1월부터 | O14: O
A15: ds_0301 | B15: 국가통계포털 | C15: 성별 및 연령별 인구와 인구밀도 | D15: http://kosis.kr/openapi/Param/statisticsParameterData.do?method=getList&itmId=00+&objL1=ALL&objL2=ALL&objL3=&objL4=&objL5=&objL6=&objL7=&objL8=&format=json&jsonVD=Y&prdSe=Y&newEstPrdCnt=3&orgId=110&tblId=DT_11001N_2013_A001 | E15: http://kosis.kr/openapi/Param/statisticsParameterData.do?method=getList&itmId=00+&objL1=ALL&objL2=ALL&objL3=&objL4=&objL5=&objL6=&objL7=&objL8=&format=json&jsonVD=Y&prdSe=Y&newEstPrdCnt=3&orgId=110&tblId=DT_11001N_2013_A001 | F15: REST | G15: JSON | H15: 1년 | I15: O | J15: O | K15: O | L15: X | N15: 2009~2020년 | O15: O
A16: ds_0401 | B16: 통계지리정보서비스 | C16: 전국 지역별 인구밀도 | D16: https://sgis.kostat.go.kr/developer/html/newOpenApi/api/dataApi/census.html#searchPopulation | E16: https://sgisapi.kostat.go.kr/OpenAPI3/stats/population.json | F16: REST | G16: JSON | H16: 1년 | J16: O | K16: O | L16: X | N16: 2015~2023년 | O16: O
A17: ds_0501 | B17: 공공데이터 포털 | C17: 전국 응급의료기관 실시간 현황 정보 | D17: https://www.data.go.kr/data/15000563/openapi.do | E17: http://apis.data.go.kr/B552657/ErmctInfoInqireService/getEmrrmRltmUsefulSckbdInfoInqire | F17: REST | G17: CSV | H17: 1일 | I17: O | J17: O | K17: O | L17: X | N17: X | O17: X
A18: ds_0502 | B18: 공공데이터 포털 | C18: 감염성질환(인플루엔자) 의료이용정보 | D18: https://www.data.go.kr/data/15089429/fileData.do | E18: https://www.data.go.kr/data/15089429/fileData.do | F18: WEB | G18: CSV | H18: 1년 | I18: O | J18: O | K18: O | L18: O | M18: O | N18: 2020~2024년 | O18: O
A19: ds_0503 | B19: 공공데이터 포털 | C19: 대기오염 통계 | D19: https://www.data.go.kr/data/15073861/openapi.do | E19: http://apis.data.go.kr/B552584/ArpltnInforInqireSvc/getCtprvnRltmMesureDnsty | F19: REST | G19: CSV | H19: 1시간 | I19: O | J19: O | K19: O | L19: X | N19: 2001~2025년(통합대기환경지수 없음) 2015년 1월 이후부터 수집 | O19: O
A20: ds_0504 | B20: 공공데이터 포털 | C20: 국경일(국경일, 공휴일, 대체공유일) 정보 | D20: https://www.data.go.kr/data/15012690/openapi.do | E20: http://apis.data.go.kr/B090041/openapi/service/SpcdeInfoService/getRestDeInfo | F20: REST | G20: CSV | H20: 7일 | I20: O | J20: O | K20: O | L20: X | N20: 2015년 1월 이후부터 수집 | O20: O
A21: ds_0505 | B21: 공공데이터 포털 | C21: 지점별 종관기상관측(ASOS) 시간자료 데이터 | D21: https://www.data.go.kr/data/15057210/openapi.do | E21: http://apis.data.go.kr/1360000/AsosHourlyInfoService/getWthrDataList | F21: REST | G21: CSV | H21: 1일 | I21: O | J21: O | K21: O | L21: X | N21: 1904년 4월부터 | O21: X
A22: ds_0506 | B22: 공공데이터 포털 | C22: 의약품사용정보 | D22: https://www.data.go.kr/data/15047819/openapi.do | E22: http://apis.data.go.kr/B551182/msupUserInfoService1.2/getAtcStp3AreaList1.2 | F22: REST | G22: CSV | H22: 1일 | I22: O | J22: O | K22: O | L22: X | N22: 2015년 1월 이후부터 수집 | O22: O
A23: ds_0507 | B23: 공공데이터 포털 | C23: 인플루엔자 시군구별 국가예방접종 현황 | D23: https://www.data.go.kr/data/15142108/fileData.do | E23: https://www.data.go.kr/data/15142108/fileData.do | F23: WEB | G23: CSV | H23: 1년 | I23: O | J23: O | K23: O | L23: O | M23: O | N23: 2015~2016절기 부터 | O23: O
A24: ds_0601 | B24: who | C24: flunet | D24: https://www.who.int/tools/flunet | E24: https://xmart-api-public.who.int/FLUMART/VIW_FNT?$format=csv | F24: FILE | G24: csv | H24: 7일 | I24: O | J24: O | K24: O | L24: X | N24: 2001년 8월 20일부터 | O24: O
A25: ds_0701 | B25: 구글 | C25: 구글 트렌드 | D25: https://trends.google.co.kr/trends/explore?geo=KR&hl=ko | E25: https://trends.google.co.kr/trends/explore?geo=KR&q=%EA%B0%90%EA%B8%B0&hl=ko | F25: WEB | G25: CSV | H25: 1일 | I25: 사용 중단(PyTrends 쿼터 제한이 심각함) | J25: 사용 중단 | K25: O | L25: X | N25: 2004년 1월 1일부터 | O25: X
A26: ds_0801 | B26: 네이버 | C26: 네이버 트렌드 | D26: https://developers.naver.com/docs/serviceapi/datalab/search/search.md | E26: https://openapi.naver.com/v1/datalab/search | F26: REST | G26: CSV | H26: 1일 | I26: O | J26: O | K26: O | L26: X | N26: 2016년 1월부터 | O26: X
A27: ds_0901 | B27: x | C27: x 트렌드 | D27: https://docs.x.com/x-api/introduction | E27: https://api.twitter.com/2/tweets/counts/recent | F27: REST | G27: CSV | H27: 7일 | I27: O | J27: O | K27: O | L27: X | N27: 2006년 7월 15일(twitter 오픈일) 부터, 유료결제(5000$) 필요 | O27: X

Sheet 수동수집데이터리스트
A1: ID | B1: 제공기관명 | C1: 서비스명 | D1: 서비스 URL | E1: 제공형태
B2: 건강보험심사평가원(HIRA) | C2: 의료정보-연구,통계-통계자료실-건강보험통계연보 | D2: https://www.hira.or.kr/bbsDummy.do?pgmid=HIRAA020045020000 | E2: PDF
B3: 질병관리청 | C3: 감염재생산지수 개념 및 방역정책에 따른 변화 | D3: https://www.kdca.go.kr/board/board.es?mid=a20602010000&bid=0034&act=view&list_no=712025 | E3: PDF
B4: 질병관리청 | C4: 질병관리청 코로나19 대응 백서 | D4: https://www.kdca.go.kr/board/board.es?mid=a20504000000&bid=0014&list_no=727575&act=view | E4: PDF
B5: 질병관리청 | C5: 국내 코로나바이러스감염증-19 재감염 추정사례 현황 및 예방접종 효과 평가 | D5: https://www.phwr.org/journal/view.html?pn=search&uid=192&vmd=Full | E5: PDF
B6: 소방안전 빅데이터 플랫폼 | C6: 질병 구급출동 현황 | D6: https://www.bigdata-119.kr/goods/goodsInfo?goods_mng_sn=366 | E6: CSV

Sheet 확산추세_필수요구데이터
B2: 필요 데이터 | C2: 데이터 카테고리 | D2: 서비스명 | E2: 주기 | F2: api 제공여부 | G2: 데이터 제공 방식 | H2: 링크 | I2: 데이터 특징 | J2: 실시간 접근 | K2: 비고 | L2: 아이브랩 검토의견
A3: ds_0101 | B3: 인플루엔자 발생현황(주간) | C3: 역학 데이터 | D3: 인플루엔자 의사환자 비율 | E3: 일주일 | F3: X | G3: csv 파일 | H3: https://dportal.kdca.go.kr/pot/is/st/influ.do | I3: - 해당 사이트에서 얻을 수 있는 정보 1. 기간에 따른 감염자 현황 2. 기간 + 연령별 감염자 현황 3. 데이터 프레임 단위 : 일주일 - 일별 데이터의 경우 who flunet 데이터를 활용해야함. but, 해당 데이터에는 검체 수 , 확진자 수 등의 데이터만 존재하며 연령 , 성별 등의 컬럼은 존재 X | J3: O | K3: 인플루엔자 중심 - 계절성 인플루엔자(현재는 없음) - 병원방문 대비 의사/환자 분율 - 주별데이터로 수집처리후/ - 특정 지역데이터는 data.go.kr에 있음 - kcda는 불가, data.go.kr/who 활용가능성 확인(전북대) | L3: - kdca(감염병포털)에서는 주간 전국 인플루엔자 의사환자분율(0.1% 단위)만을 제공, 따라서 정확한 환자수를 알려면 주간 외래환자 수를 알아야 역산이 가능 - 그러나 hira, kosis에선 연간 외래환자 수만 제공되므로, 주간 인플루엔자 환자수는 얻을 수 없음 - who flunet의 경우 전수조사가 아닌 표본검체 중 종류별 인플루엔자 바이러스 검출 건수이므로 이 또한 비율적인 수치이지, 정확한 수치는 아님.
A4: ds_0502 | B4: 지역별 감염 발생 현황 (월별) | D4: 감염성질환(인플루엔자) 의료이용정보 | E4: 월별 | I4: 데이터 업데이트 주기는 주별로 진행 따라서 월별 데이터는 실시간으로 업데이트 가능 | J4: O | K4: - 예측 주기는 : - 1일, 3일, 7일(장기예측) | L4: - https://www.data.go.kr/data/15089429/fileData.do - 국민건강보험공단_감염성질환(인플루엔자) 의료이용정보에 시도별, 일간 인플루엔자 외래환자 수 및 입원환자 수 데이터 제공 - 매년 8월~9월 경에 작년 데이터를 업로드
A5: ds_0502 | B5: 연령대별, 성별 감염률 | C5: 역학 데이터 | D5: 감염병 연령·성별별 발생현황 | E5: 주별 | I5: 감염자 수 데이터와 함께 존재 | L5: - kdca(감염병포털)의 경우 성별 구별 X, 0세/1~6세/7~12세/13~18세/19~49세/50~64세/65세 이상으로 구별 - 국민건강보험공단 데이터는 성별 구별 O, 0~5세/6~11세/12세~17세/18~44세/45~64세/65세 이상으로 구별
A6: ds_0507 | B6: 백신 접종률 (지역별, 연령별) | C6: 예방접종 데이터 | D6: 예방접종 통계 | E6: 주별 | F6: X | G6: API | H6: https://www.data.go.kr/data/15142108/fileData.do | I6: 1. 지역별 데이터 제공 2. 성별 별 데이터 제공 | J6: O | K6: 해당 지역 수준 통계데이터 - 정책/참고데이터는 관리가 필요 | L6: - 질병관리청_인플루엔자 시군구별 국가예방접종 현황의 경우 국가지원 백신접종(어린이, 임산부, 65세 이상)대상에 대한 시군구, 성별 단위 연간 수치 제공 - https://gsis.kwdi.re.kr/statHtml/statHtml.do?orgId=338&tblId=DT_GIABRM16_020 의 경우 성별, 연령 구별 없이 시군구별에 대한 표본조사로 접종 비율 제공
A7: ds_0202 | B7: 병원 방문 환자 수 (인플루엔자 의사환자 비율 포함) | C7: 진료 데이터 | D7: 인플루엔자 의사환자 비율 | E7: 주별 | F7: O | G7: API | H7: https://opendata.hira.or.kr/op/opc/olap4thDsInfoTab1.do | I7: - 데이터 특징 1. 지역별 데이터 제공 2. 단순 인플루엔자 뿐 아니라 동물 매개 인플루엔자 , 바이러스가 확인되지 않은 인플루엔자 , 기타 증상을 동반한 인플루엔자 등 인플루엔자 관련 질환을 전부 질병 코드를 통해 확인 가능 3. 주기는 매월 집계됨. 단, 조회 시 최근 8개월전 데이터까지 조회 가능 | J7: X | K7: data.go.kr 수준 확인 | L7: - 감염병포털(kdca)에 의사환자 비율정보 제공 확인
A8: X | B8: 사망률 및 합병증 발생률 | C8: 중증도 데이터 | D8: 인플루엔자 사망자 및 합병증 통계 | E8: 주별 | K8: - 관련 보고서 존재여부 | L8: - 일부 논문 Flu 추정사망자 자료(국내 인플루엔자 사망관련 연구 동향, 박충민 외, 2021)
A9: ds_1201 | B9: 신규 바이러스 발생 여부 (유형별, 변종별 감염률) | C9: 변이/바이러스 유전자 데이터 | D9: 인플루엔자 바이러스 주별 검출율 | E9: 주별 | K9: - Inf-> 변종 - Who Flunet… 활용 필요
A10: ds_0505 | B10: 온도, 습도, 기후 지수 | C10: 기상 데이터 | D10: 국가기후데이터센터, 공공데이터포털 기상통계 | E10: 주별 | F10: O | G10: API를 통한 JSON 방식 | H10: https://www.data.go.kr/data/15057210/openapi.do | I10: - 데이터 특징 1. 지역별 기온 , 온도 , 습도 , 강수량 등의 데이터 확보 가능 2. 데이터 프레임 단위 : 시간 | J10: O | K10: 필요 시간 범위 확인요 - 동수준 1회 요청 회수,1일 | L10: - 295개 지점데이터(시,군)로 동수준데이터는 아님
A11: ds_0503 | B11: 미세먼지 (PM2.5), 대기오염 (CO, NO2 등) | C11: 환경 데이터 | D11: 대기오염 통계 | E11: 주별 | F11: O | G11: API | H11: https://www.data.go.kr/data/15073861/openapi.do | I11: - 데이터 특징 1. 지역별 시간별 데이터 제공 2. PM10 , PM2.5 , O3 , NO2 , CO 등 요소별 데이터 제공 | J11: O | L11: - 측정소 실시간 대기오염정보(668개 측정소로, 동수준은 아님)/조회시간 이전 24시간 이력데이터 - 시도별 실시간 대기오염정보(17개 시도)의 최근 시간별 측정소 실시간 데이터==> 이 API로 처리가 적합하나, 동수준은 아닌점을 고려 필요
A12: ds_0901 ds_0902 | B12: 검색 트렌드 (인플루엔자 키워드 트렌드) | C12: 사회행동 데이터 | D12: 네이버 데이터랩, 구글 트렌드 | E12: 주별 | K12: - 인플루엔자관련, 구굴/@네이버/@트위터 | L12: - 트위터의 경우 지나간 데이터는 수집 불가, 실시간 트렌드(키워드 30건, 정확한 트윗 수치 제공)만 확인 가능 - 구글, 네이버 경우 관심도 최대치일 때 100을 기준으로, 퍼센트 단위로 확인 가능 - 구글의 경우 1분(범위 1시간, 4시간), 8분(범위 1일), 1시간(범위 7일), 1일(범위 90일), 주간(범위 5년), 월간(그 이상 범위)로 수집 가능 - 네이버의 경우 관심도 최대치일 때 100을 기준으로, 일 단위 퍼센트 단위로 확인 가능
A13: ds_0401 | B13: 인구 밀도 (지역별) | C13: 인구학적 데이터 | D13: 주민등록 인구통계, 통계청 KOSIS | E13: 주별/월별 | F13: O | G13: API | H13: https://sgis.kostat.go.kr/developer/html/newOpenApi/api/dataApi/census.html | I13: - 데이터 특징 1. 지역별로 제공 2. 연도별 제공도 가능 | J13: O | L13: - 시도,시군구,읍면동 단위 총 인구수 수집 가능
A14: X | B14: 감염재생산지수 (Rt) | C14: 공중보건 정책 데이터 | D14: 감염재생산지수 주간보고서 | E14: 주별 | K14: - 입력/관리 | L14: - 인플루엔자 감염재생산지수 데이터 미확인
A15: ds_0504 | B15: 인플루엔자 발생 시 국경일/연휴 여+B15:O15부 | C15: 계절성 지표 | D15: 한국천문연구원 달력, 공공데이터포털 | E15: 주별 | F15: O | G15: API | H15: https://www.data.go.kr/data/15012690/openapi.do | J15: O | L15: - 연, 월별로 국경일, 공휴일 정보 수집 가능
A16: ds_0506 | B16: 해열제, 종합감기약 등 약품 사용률 | D16: 공공데이터포털 | F16: O | G16: API | H16: https://www.data.go.kr/data/15047819/openapi.do?utm_source=chatgpt.com#tab_layer_prcuse_exam | I16: 약효분류군 / ATC코드별 / 성분별의 지역별 / 의료기관 종별 / 상병별 사용량 조회 가능 | J16: O | L16: - 진료년월, 보험자 구분, 조제처방구분, 시도/시군구코드를 통해 ATC 코드별 지역별 사용량 목록 수집 가능
B17: 인플루엔자 의사환자 발생현황 | C17: 역학 데이터 | D17: 질병 관리청 | E17: 주별 | F17: X | G17: pdf | H17: https://www.kdca.go.kr/board/board.es?mid=a21106020000&bid=0055 | I17: python을 통해 텍스트 추출 후 수집 해야 함. | J17: X | K17: -발열/인후통 등… - 입력/관리 필요 | L17: - 감염병 포털 서비스로 통합 처리
B20: 초록색: 아이브랩에서 현재 확보한 데이터 소스 노란색: 아이브랩 측에서 해당 요구사항에 완전히 부합된다고 평가 흰색: 현재 확보되지 않은 데이터

Sheet 기타
A1: 환경공단 시도구분
A2: 환경공단 측정소
A3: 시도 | B3: Station수
A4: 서울 | B4: 40
A5: 경기 | B5: 127
A6: 인천 | B6: 42
A7: 강원 | B7: 40
A8: 충북 | B8: 34
A9: 충남 | B9: 53
A10: 대전 | B10: 14
A11: 세종 | B11: 6
A12: 경북 | B12: 53
A13: 경남 | B13: 50
A14: 전북 | B14: 48
A15: 전남 | B15: 50
... A20: 제주 | B20: 14
A21: 합계 | B21: =SUM(B4:B20) -> 674

Sheet Sheet1
A1: ATC 3단계 코드 | B1: 영문 명칭 | C1: 한국어 명칭 | D1: 감염병관련
A2: A01A | B2: STOMATOLOGICAL PREPARATIONS | C2: 구강용 제제 (치과·구강 치료용)
A3: A02A | B3: ANTACIDS | C3: 제산제
A4: A02B | B4: DRUGS FOR PEPTIC ULCER AND GASTRO-OESOPHAGEAL REFLUX DISEASE (GORD) | C4: 소화성 궤양·위식도 역류질환 치료제
A5: A03A | B5: DRUGS FOR FUNCTIONAL GASTROINTESTINAL DISORDERS | C5: 기능성 위장관 질환 치료제
A6: A03B | B6: BELLADONNA AND DERIVATIVES, PLAIN | C6: 벨라돈나 및 유도체 단일제
A7: A03C | B7: ANTISPASMODICS IN COMBINATION WITH PSYCHOLEPTICS | C7: 정신안정제와 결합된 항경련제
A8: A03D | B8: ANTISPASMODICS IN COMBINATION WITH ANALGESICS | C8: 진통제와 결합된 항경련제
A9: A03F | B9: PROPULSIVES | C9: 위장운동 촉진제
A10: A04A | B10: ANTIEMETICS AND ANTINAUSEANTS | C10: 구역·구토 억제제
A11: A05A | B11: BILE THERAPY | C11: 담즙 치료제
A12: A05B | B12: LIVER THERAPY, LIPOTROPICS | C12: 간 치료제, 지질 개선제
A13: A06A | B13: DRUGS FOR CONSTIPATION | C13: 변비약
... A188: J04B | B188: DRUGS FOR TREATMENT OF LEPRA | C188: 나병 치료제
A189: J05A | B189: DIRECT ACTING ANTIVIRALS | C189: 직접작용 항바이러스제 | D189: O
A190: J06A | B190: IMMUNE SERA | C190: 면역 혈청 | D190: O
A191: J06B | B191: IMMUNOGLOBULINS | C191: 면역글로불린 | D191: O
A192: J07A | B192: BACTERIAL VACCINES | C192: 세균 백신
A193: J07B | B193: VIRAL VACCINES | C193: 바이러스 백신 | D193: O
A194: J07C | B194: BACTERIAL AND VIRAL VACCINES, COMBINED | C194: 세균+바이러스 백신 조합 | D194: O
A195: J07X | B195: OTHER VACCINES | C195: 기타 백신
A196: L01A | B196: ALKYLATING AGENTS | C196: 알킬화제 (항암제)
A197: L01B | B197: ANTIMETABOLITES | C197: 항대사제
A198: L01C | B198: PLANT ALKALOIDS AND OTHER NATURAL PRODUCTS | C198: 식물알칼로이드 및 천연물 항암제
A199: L01D | B199: CYTOTOXIC ANTIBIOTICS AND RELATED SUBSTANCES | C199: 세포독성 항생제 및 관련물질
A200: L01E | B200: PROTEIN KINASE INHIBITORS | C200: 단백질 키나제 억제제
A201: L01F | B201: MONOCLONAL ANTIBODIES AND ANTIBODY DRUG CONJUGATES | C201: 단클론항체 및 항체약물결합제
A202: L01X | B202: OTHER ANTINEOPLASTIC AGENTS | C202: 기타 항암제
A203: L02A | B203: HORMONES AND RELATED AGENTS | C203: 호르몬 및 관련제
A204: L02B | B204: HORMONE ANTAGONISTS AND RELATED AGENTS | C204: 호르몬 길항제 및 관련제
A205: L03A | B205: IMMUNOSTIMULANTS | C205: 면역자극제 | D205: O
A206: L04A | B206: IMMUNOSUPPRESSANTS | C206: 면역억제제
A207: M01A | B207: ANTIINFLAMMATORY AND ANTIRHEUMATIC PRODUCTS, NON-STEROIDS | C207: 비스테로이드성 소염진통제
A208: M01B | B208: ANTIINFLAMMATORY/ANTIRHEUMATIC AGENTS IN COMBINATION | C208: 소염·항류머티즘제 조합
A209: M01C | B209: SPECIFIC ANTIRHEUMATIC AGENTS | C209: 특정 항류머티즘제
A210: M02A | B210: TOPICAL PRODUCTS FOR JOINT AND MUSCULAR PAIN | C210: 관절·근육 통증용 국소제
A211: M03A | B211: MUSCLE RELAXANTS, PERIPHERALLY ACTING AGENTS | C211: 말초작용 근이완제
A212: M03B | B212: MUSCLE RELAXANTS, CENTRALLY ACTING AGENTS | C212: 중추작용 근이완제
A213: M03C | B213: MUSCLE RELAXANTS, DIRECTLY ACTING AGENTS | C213: 직접작용 근이완제
A214: M04A | B214: ANTIGOUT PREPARATIONS | C214: 통풍 치료제
...
